ERROR:root:
Traceback (most recent call last):
  File "chapter4.py", line 6, in <module>
    raise Exception
Exception
